telegram.vendor.ptb_urllib3.urllib3.connectionpool - WARNING - Retrying (Retry(total=2, connect=None, read=None, redirect=None)) after connection broken by 'NewConnectionError('<telegram.vendor.ptb_urllib3.urllib3.contrib.socks.SOCKSHTTPSConnection object at 0x10c5980b8>: Failed to establish a new connection: 0x02: Connection not allowed by ruleset')': /bot883704044:AAEgGQKBqM-5tOQnApLj--n-T7Hhub8OL4w/deleteWebhook
telegram.vendor.ptb_urllib3.urllib3.connectionpool - WARNING - Retrying (Retry(total=1, connect=None, read=None, redirect=None)) after connection broken by 'NewConnectionError('<telegram.vendor.ptb_urllib3.urllib3.contrib.socks.SOCKSHTTPSConnection object at 0x10c5987f0>: Failed to establish a new connection: 0x02: Connection not allowed by ruleset')': /bot883704044:AAEgGQKBqM-5tOQnApLj--n-T7Hhub8OL4w/deleteWebhook
telegram.vendor.ptb_urllib3.urllib3.connectionpool - WARNING - Retrying (Retry(total=0, connect=None, read=None, redirect=None)) after connection broken by 'NewConnectionError('<telegram.vendor.ptb_urllib3.urllib3.contrib.socks.SOCKSHTTPSConnection object at 0x10c5a5940>: Failed to establish a new connection: 0x02: Connection not allowed by ruleset')': /bot883704044:AAEgGQKBqM-5tOQnApLj--n-T7Hhub8OL4w/deleteWebhook
telegram.ext.updater - ERROR - Error while bootstrap del webhook: urllib3 HTTPError SOCKSHTTPSConnectionPool(host='api.telegram.org', port=443): Max retries exceeded with url: /bot883704044:AAEgGQKBqM-5tOQnApLj--n-T7Hhub8OL4w/deleteWebhook (Caused by NewConnectionError('<telegram.vendor.ptb_urllib3.urllib3.contrib.socks.SOCKSHTTPSConnection object at 0x10c5a5be0>: Failed to establish a new connection: 0x02: Connection not allowed by ruleset'))
telegram.ext.updater - WARNING - Failed bootstrap phase; try=1 max_retries=-1
telegram.vendor.ptb_urllib3.urllib3.connectionpool - WARNING - Retrying (Retry(total=2, connect=None, read=None, redirect=None)) after connection broken by 'NewConnectionError('<telegram.vendor.ptb_urllib3.urllib3.contrib.socks.SOCKSHTTPSConnection object at 0x10c5a5c88>: Failed to establish a new connection: 0x02: Connection not allowed by ruleset')': /bot883704044:AAEgGQKBqM-5tOQnApLj--n-T7Hhub8OL4w/deleteWebhook
telegram.vendor.ptb_urllib3.urllib3.connectionpool - WARNING - Retrying (Retry(total=1, connect=None, read=None, redirect=None)) after connection broken by 'NewConnectionError('<telegram.vendor.ptb_urllib3.urllib3.contrib.socks.SOCKSHTTPSConnection object at 0x10c5c3160>: Failed to establish a new connection: 0x02: Connection not allowed by ruleset')': /bot883704044:AAEgGQKBqM-5tOQnApLj--n-T7Hhub8OL4w/deleteWebhook
telegram.vendor.ptb_urllib3.urllib3.connectionpool - WARNING - Retrying (Retry(total=0, connect=None, read=None, redirect=None)) after connection broken by 'NewConnectionError('<telegram.vendor.ptb_urllib3.urllib3.contrib.socks.SOCKSHTTPSConnection object at 0x10c5a5ac8>: Failed to establish a new connection: 0x02: Connection not allowed by ruleset')': /bot883704044:AAEgGQKBqM-5tOQnApLj--n-T7Hhub8OL4w/deleteWebhook
telegram.ext.updater - ERROR - Error while bootstrap del webhook: urllib3 HTTPError SOCKSHTTPSConnectionPool(host='api.telegram.org', port=443): Max retries exceeded with url: /bot883704044:AAEgGQKBqM-5tOQnApLj--n-T7Hhub8OL4w/deleteWebhook (Caused by NewConnectionError('<telegram.vendor.ptb_urllib3.urllib3.contrib.socks.SOCKSHTTPSConnection object at 0x10c5a5f28>: Failed to establish a new connection: 0x02: Connection not allowed by ruleset'))
telegram.ext.updater - WARNING - Failed bootstrap phase; try=2 max_retries=-1
telegram.vendor.ptb_urllib3.urllib3.connectionpool - WARNING - Retrying (Retry(total=2, connect=None, read=None, redirect=None)) after connection broken by 'NewConnectionError('<telegram.vendor.ptb_urllib3.urllib3.contrib.socks.SOCKSHTTPSConnection object at 0x10c5a5e80>: Failed to establish a new connection: 0x02: Connection not allowed by ruleset')': /bot883704044:AAEgGQKBqM-5tOQnApLj--n-T7Hhub8OL4w/deleteWebhook
telegram.vendor.ptb_urllib3.urllib3.connectionpool - WARNING - Retrying (Retry(total=1, connect=None, read=None, redirect=None)) after connection broken by 'NewConnectionError('<telegram.vendor.ptb_urllib3.urllib3.contrib.socks.SOCKSHTTPSConnection object at 0x10c5986a0>: Failed to establish a new connection: 0x02: Connection not allowed by ruleset')': /bot883704044:AAEgGQKBqM-5tOQnApLj--n-T7Hhub8OL4w/deleteWebhook
telegram.vendor.ptb_urllib3.urllib3.connectionpool - WARNING - Retrying (Retry(total=0, connect=None, read=None, redirect=None)) after connection broken by 'NewConnectionError('<telegram.vendor.ptb_urllib3.urllib3.contrib.socks.SOCKSHTTPSConnection object at 0x10c5c3208>: Failed to establish a new connection: 0x02: Connection not allowed by ruleset')': /bot883704044:AAEgGQKBqM-5tOQnApLj--n-T7Hhub8OL4w/deleteWebhook
telegram.ext.updater - ERROR - Error while bootstrap del webhook: urllib3 HTTPError SOCKSHTTPSConnectionPool(host='api.telegram.org', port=443): Max retries exceeded with url: /bot883704044:AAEgGQKBqM-5tOQnApLj--n-T7Hhub8OL4w/deleteWebhook (Caused by NewConnectionError('<telegram.vendor.ptb_urllib3.urllib3.contrib.socks.SOCKSHTTPSConnection object at 0x10c5c3400>: Failed to establish a new connection: 0x02: Connection not allowed by ruleset'))
telegram.ext.updater - WARNING - Failed bootstrap phase; try=3 max_retries=-1
telegram.vendor.ptb_urllib3.urllib3.connectionpool - WARNING - Retrying (Retry(total=2, connect=None, read=None, redirect=None)) after connection broken by 'NewConnectionError('<telegram.vendor.ptb_urllib3.urllib3.contrib.socks.SOCKSHTTPSConnection object at 0x10c5c34a8>: Failed to establish a new connection: 0x02: Connection not allowed by ruleset')': /bot883704044:AAEgGQKBqM-5tOQnApLj--n-T7Hhub8OL4w/deleteWebhook
telegram.vendor.ptb_urllib3.urllib3.connectionpool - WARNING - Retrying (Retry(total=1, connect=None, read=None, redirect=None)) after connection broken by 'NewConnectionError('<telegram.vendor.ptb_urllib3.urllib3.contrib.socks.SOCKSHTTPSConnection object at 0x10c5c3908>: Failed to establish a new connection: 0x02: Connection not allowed by ruleset')': /bot883704044:AAEgGQKBqM-5tOQnApLj--n-T7Hhub8OL4w/deleteWebhook
telegram.vendor.ptb_urllib3.urllib3.connectionpool - WARNING - Retrying (Retry(total=0, connect=None, read=None, redirect=None)) after connection broken by 'NewConnectionError('<telegram.vendor.ptb_urllib3.urllib3.contrib.socks.SOCKSHTTPSConnection object at 0x10c5c39b0>: Failed to establish a new connection: 0x02: Connection not allowed by ruleset')': /bot883704044:AAEgGQKBqM-5tOQnApLj--n-T7Hhub8OL4w/deleteWebhook
telegram.ext.updater - ERROR - Error while bootstrap del webhook: urllib3 HTTPError SOCKSHTTPSConnectionPool(host='api.telegram.org', port=443): Max retries exceeded with url: /bot883704044:AAEgGQKBqM-5tOQnApLj--n-T7Hhub8OL4w/deleteWebhook (Caused by NewConnectionError('<telegram.vendor.ptb_urllib3.urllib3.contrib.socks.SOCKSHTTPSConnection object at 0x10c5c3ba8>: Failed to establish a new connection: 0x02: Connection not allowed by ruleset'))
telegram.ext.updater - WARNING - Failed bootstrap phase; try=4 max_retries=-1
telegram.ext.updater - INFO - Received signal 2 (SIGINT), stopping...
telegram.vendor.ptb_urllib3.urllib3.connectionpool - WARNING - Retrying (Retry(total=2, connect=None, read=None, redirect=None)) after connection broken by 'NewConnectionError('<telegram.vendor.ptb_urllib3.urllib3.contrib.socks.SOCKSHTTPSConnection object at 0x106024fd0>: Failed to establish a new connection: 0x02: Connection not allowed by ruleset')': /bot883704044:AAEgGQKBqM-5tOQnApLj--n-T7Hhub8OL4w/deleteWebhook
telegram.vendor.ptb_urllib3.urllib3.connectionpool - WARNING - Retrying (Retry(total=1, connect=None, read=None, redirect=None)) after connection broken by 'NewConnectionError('<telegram.vendor.ptb_urllib3.urllib3.contrib.socks.SOCKSHTTPSConnection object at 0x1060397b8>: Failed to establish a new connection: 0x02: Connection not allowed by ruleset')': /bot883704044:AAEgGQKBqM-5tOQnApLj--n-T7Hhub8OL4w/deleteWebhook
telegram.vendor.ptb_urllib3.urllib3.connectionpool - WARNING - Retrying (Retry(total=0, connect=None, read=None, redirect=None)) after connection broken by 'NewConnectionError('<telegram.vendor.ptb_urllib3.urllib3.contrib.socks.SOCKSHTTPSConnection object at 0x106043940>: Failed to establish a new connection: 0x02: Connection not allowed by ruleset')': /bot883704044:AAEgGQKBqM-5tOQnApLj--n-T7Hhub8OL4w/deleteWebhook
telegram.ext.updater - ERROR - Error while bootstrap del webhook: urllib3 HTTPError SOCKSHTTPSConnectionPool(host='api.telegram.org', port=443): Max retries exceeded with url: /bot883704044:AAEgGQKBqM-5tOQnApLj--n-T7Hhub8OL4w/deleteWebhook (Caused by NewConnectionError('<telegram.vendor.ptb_urllib3.urllib3.contrib.socks.SOCKSHTTPSConnection object at 0x106043be0>: Failed to establish a new connection: 0x02: Connection not allowed by ruleset'))
telegram.ext.updater - WARNING - Failed bootstrap phase; try=1 max_retries=-1
telegram.vendor.ptb_urllib3.urllib3.connectionpool - WARNING - Retrying (Retry(total=2, connect=None, read=None, redirect=None)) after connection broken by 'NewConnectionError('<telegram.vendor.ptb_urllib3.urllib3.contrib.socks.SOCKSHTTPSConnection object at 0x106043c88>: Failed to establish a new connection: 0x02: Connection not allowed by ruleset')': /bot883704044:AAEgGQKBqM-5tOQnApLj--n-T7Hhub8OL4w/deleteWebhook
telegram.vendor.ptb_urllib3.urllib3.connectionpool - WARNING - Retrying (Retry(total=1, connect=None, read=None, redirect=None)) after connection broken by 'NewConnectionError('<telegram.vendor.ptb_urllib3.urllib3.contrib.socks.SOCKSHTTPSConnection object at 0x106063160>: Failed to establish a new connection: 0x02: Connection not allowed by ruleset')': /bot883704044:AAEgGQKBqM-5tOQnApLj--n-T7Hhub8OL4w/deleteWebhook
telegram.vendor.ptb_urllib3.urllib3.connectionpool - WARNING - Retrying (Retry(total=0, connect=None, read=None, redirect=None)) after connection broken by 'NewConnectionError('<telegram.vendor.ptb_urllib3.urllib3.contrib.socks.SOCKSHTTPSConnection object at 0x106043f28>: Failed to establish a new connection: 0x02: Connection not allowed by ruleset')': /bot883704044:AAEgGQKBqM-5tOQnApLj--n-T7Hhub8OL4w/deleteWebhook
telegram.ext.updater - ERROR - Error while bootstrap del webhook: urllib3 HTTPError SOCKSHTTPSConnectionPool(host='api.telegram.org', port=443): Max retries exceeded with url: /bot883704044:AAEgGQKBqM-5tOQnApLj--n-T7Hhub8OL4w/deleteWebhook (Caused by NewConnectionError('<telegram.vendor.ptb_urllib3.urllib3.contrib.socks.SOCKSHTTPSConnection object at 0x106043ef0>: Failed to establish a new connection: 0x02: Connection not allowed by ruleset'))
telegram.ext.updater - WARNING - Failed bootstrap phase; try=2 max_retries=-1
telegram.vendor.ptb_urllib3.urllib3.connectionpool - WARNING - Retrying (Retry(total=2, connect=None, read=None, redirect=None)) after connection broken by 'NewConnectionError('<telegram.vendor.ptb_urllib3.urllib3.contrib.socks.SOCKSHTTPSConnection object at 0x106043e80>: Failed to establish a new connection: 0x02: Connection not allowed by ruleset')': /bot883704044:AAEgGQKBqM-5tOQnApLj--n-T7Hhub8OL4w/deleteWebhook
telegram.vendor.ptb_urllib3.urllib3.connectionpool - WARNING - Retrying (Retry(total=1, connect=None, read=None, redirect=None)) after connection broken by 'NewConnectionError('<telegram.vendor.ptb_urllib3.urllib3.contrib.socks.SOCKSHTTPSConnection object at 0x106039668>: Failed to establish a new connection: 0x02: Connection not allowed by ruleset')': /bot883704044:AAEgGQKBqM-5tOQnApLj--n-T7Hhub8OL4w/deleteWebhook
telegram.vendor.ptb_urllib3.urllib3.connectionpool - WARNING - Retrying (Retry(total=0, connect=None, read=None, redirect=None)) after connection broken by 'NewConnectionError('<telegram.vendor.ptb_urllib3.urllib3.contrib.socks.SOCKSHTTPSConnection object at 0x106063208>: Failed to establish a new connection: 0x02: Connection not allowed by ruleset')': /bot883704044:AAEgGQKBqM-5tOQnApLj--n-T7Hhub8OL4w/deleteWebhook
telegram.ext.updater - ERROR - Error while bootstrap del webhook: urllib3 HTTPError SOCKSHTTPSConnectionPool(host='api.telegram.org', port=443): Max retries exceeded with url: /bot883704044:AAEgGQKBqM-5tOQnApLj--n-T7Hhub8OL4w/deleteWebhook (Caused by NewConnectionError('<telegram.vendor.ptb_urllib3.urllib3.contrib.socks.SOCKSHTTPSConnection object at 0x106063400>: Failed to establish a new connection: 0x02: Connection not allowed by ruleset'))
telegram.ext.updater - WARNING - Failed bootstrap phase; try=3 max_retries=-1
telegram.vendor.ptb_urllib3.urllib3.connectionpool - WARNING - Retrying (Retry(total=2, connect=None, read=None, redirect=None)) after connection broken by 'NewConnectionError('<telegram.vendor.ptb_urllib3.urllib3.contrib.socks.SOCKSHTTPSConnection object at 0x1060634a8>: Failed to establish a new connection: 0x02: Connection not allowed by ruleset')': /bot883704044:AAEgGQKBqM-5tOQnApLj--n-T7Hhub8OL4w/deleteWebhook
telegram.vendor.ptb_urllib3.urllib3.connectionpool - WARNING - Retrying (Retry(total=1, connect=None, read=None, redirect=None)) after connection broken by 'NewConnectionError('<telegram.vendor.ptb_urllib3.urllib3.contrib.socks.SOCKSHTTPSConnection object at 0x106063908>: Failed to establish a new connection: 0x02: Connection not allowed by ruleset')': /bot883704044:AAEgGQKBqM-5tOQnApLj--n-T7Hhub8OL4w/deleteWebhook
telegram.vendor.ptb_urllib3.urllib3.connectionpool - WARNING - Retrying (Retry(total=0, connect=None, read=None, redirect=None)) after connection broken by 'NewConnectionError('<telegram.vendor.ptb_urllib3.urllib3.contrib.socks.SOCKSHTTPSConnection object at 0x1060639b0>: Failed to establish a new connection: 0x02: Connection not allowed by ruleset')': /bot883704044:AAEgGQKBqM-5tOQnApLj--n-T7Hhub8OL4w/deleteWebhook
telegram.ext.updater - ERROR - Error while bootstrap del webhook: urllib3 HTTPError SOCKSHTTPSConnectionPool(host='api.telegram.org', port=443): Max retries exceeded with url: /bot883704044:AAEgGQKBqM-5tOQnApLj--n-T7Hhub8OL4w/deleteWebhook (Caused by NewConnectionError('<telegram.vendor.ptb_urllib3.urllib3.contrib.socks.SOCKSHTTPSConnection object at 0x106063ba8>: Failed to establish a new connection: 0x02: Connection not allowed by ruleset'))
telegram.ext.updater - WARNING - Failed bootstrap phase; try=4 max_retries=-1
telegram.ext.updater - INFO - Received signal 2 (SIGINT), stopping...
telegram.vendor.ptb_urllib3.urllib3.connectionpool - WARNING - Retrying (Retry(total=2, connect=None, read=None, redirect=None)) after connection broken by 'NewConnectionError('<telegram.vendor.ptb_urllib3.urllib3.contrib.socks.SOCKSHTTPSConnection object at 0x1028b2080>: Failed to establish a new connection: 0x02: Connection not allowed by ruleset')': /bot883704044:AAEgGQKBqM-5tOQnApLj--n-T7Hhub8OL4w/deleteWebhook
telegram.vendor.ptb_urllib3.urllib3.connectionpool - WARNING - Retrying (Retry(total=1, connect=None, read=None, redirect=None)) after connection broken by 'NewConnectionError('<telegram.vendor.ptb_urllib3.urllib3.contrib.socks.SOCKSHTTPSConnection object at 0x1028b2828>: Failed to establish a new connection: 0x02: Connection not allowed by ruleset')': /bot883704044:AAEgGQKBqM-5tOQnApLj--n-T7Hhub8OL4w/deleteWebhook
telegram.vendor.ptb_urllib3.urllib3.connectionpool - WARNING - Retrying (Retry(total=0, connect=None, read=None, redirect=None)) after connection broken by 'NewConnectionError('<telegram.vendor.ptb_urllib3.urllib3.contrib.socks.SOCKSHTTPSConnection object at 0x1028bf9b0>: Failed to establish a new connection: 0x02: Connection not allowed by ruleset')': /bot883704044:AAEgGQKBqM-5tOQnApLj--n-T7Hhub8OL4w/deleteWebhook
telegram.ext.updater - ERROR - Error while bootstrap del webhook: urllib3 HTTPError SOCKSHTTPSConnectionPool(host='api.telegram.org', port=443): Max retries exceeded with url: /bot883704044:AAEgGQKBqM-5tOQnApLj--n-T7Hhub8OL4w/deleteWebhook (Caused by NewConnectionError('<telegram.vendor.ptb_urllib3.urllib3.contrib.socks.SOCKSHTTPSConnection object at 0x1028bfc18>: Failed to establish a new connection: 0x02: Connection not allowed by ruleset'))
telegram.ext.updater - WARNING - Failed bootstrap phase; try=1 max_retries=-1
telegram.vendor.ptb_urllib3.urllib3.connectionpool - WARNING - Retrying (Retry(total=2, connect=None, read=None, redirect=None)) after connection broken by 'NewConnectionError('<telegram.vendor.ptb_urllib3.urllib3.contrib.socks.SOCKSHTTPSConnection object at 0x1028a0ef0>: Failed to establish a new connection: 0x02: Connection not allowed by ruleset')': /bot883704044:AAEgGQKBqM-5tOQnApLj--n-T7Hhub8OL4w/deleteWebhook
telegram.vendor.ptb_urllib3.urllib3.connectionpool - WARNING - Retrying (Retry(total=1, connect=None, read=None, redirect=None)) after connection broken by 'NewConnectionError('<telegram.vendor.ptb_urllib3.urllib3.contrib.socks.SOCKSHTTPSConnection object at 0x1028dc1d0>: Failed to establish a new connection: 0x02: Connection not allowed by ruleset')': /bot883704044:AAEgGQKBqM-5tOQnApLj--n-T7Hhub8OL4w/deleteWebhook
telegram.vendor.ptb_urllib3.urllib3.connectionpool - WARNING - Retrying (Retry(total=0, connect=None, read=None, redirect=None)) after connection broken by 'NewConnectionError('<telegram.vendor.ptb_urllib3.urllib3.contrib.socks.SOCKSHTTPSConnection object at 0x1028bfc88>: Failed to establish a new connection: 0x02: Connection not allowed by ruleset')': /bot883704044:AAEgGQKBqM-5tOQnApLj--n-T7Hhub8OL4w/deleteWebhook
telegram.ext.updater - ERROR - Error while bootstrap del webhook: urllib3 HTTPError SOCKSHTTPSConnectionPool(host='api.telegram.org', port=443): Max retries exceeded with url: /bot883704044:AAEgGQKBqM-5tOQnApLj--n-T7Hhub8OL4w/deleteWebhook (Caused by NewConnectionError('<telegram.vendor.ptb_urllib3.urllib3.contrib.socks.SOCKSHTTPSConnection object at 0x1028bfe48>: Failed to establish a new connection: 0x02: Connection not allowed by ruleset'))
telegram.ext.updater - WARNING - Failed bootstrap phase; try=2 max_retries=-1
telegram.ext.updater - INFO - Received signal 2 (SIGINT), stopping...
telegram.vendor.ptb_urllib3.urllib3.connectionpool - WARNING - Retrying (Retry(total=2, connect=None, read=None, redirect=None)) after connection broken by 'NewConnectionError('<telegram.vendor.ptb_urllib3.urllib3.contrib.socks.SOCKSHTTPSConnection object at 0x10c83b0b8>: Failed to establish a new connection: 0x02: Connection not allowed by ruleset')': /bot883704044:AAEgGQKBqM-5tOQnApLj--n-T7Hhub8OL4w/deleteWebhook
telegram.vendor.ptb_urllib3.urllib3.connectionpool - WARNING - Retrying (Retry(total=1, connect=None, read=None, redirect=None)) after connection broken by 'NewConnectionError('<telegram.vendor.ptb_urllib3.urllib3.contrib.socks.SOCKSHTTPSConnection object at 0x10c83b748>: Failed to establish a new connection: 0x02: Connection not allowed by ruleset')': /bot883704044:AAEgGQKBqM-5tOQnApLj--n-T7Hhub8OL4w/deleteWebhook
telegram.vendor.ptb_urllib3.urllib3.connectionpool - WARNING - Retrying (Retry(total=0, connect=None, read=None, redirect=None)) after connection broken by 'NewConnectionError('<telegram.vendor.ptb_urllib3.urllib3.contrib.socks.SOCKSHTTPSConnection object at 0x10c848940>: Failed to establish a new connection: 0x02: Connection not allowed by ruleset')': /bot883704044:AAEgGQKBqM-5tOQnApLj--n-T7Hhub8OL4w/deleteWebhook
telegram.ext.updater - ERROR - Error while bootstrap del webhook: urllib3 HTTPError SOCKSHTTPSConnectionPool(host='api.telegram.org', port=443): Max retries exceeded with url: /bot883704044:AAEgGQKBqM-5tOQnApLj--n-T7Hhub8OL4w/deleteWebhook (Caused by NewConnectionError('<telegram.vendor.ptb_urllib3.urllib3.contrib.socks.SOCKSHTTPSConnection object at 0x10c848be0>: Failed to establish a new connection: 0x02: Connection not allowed by ruleset'))
telegram.ext.updater - WARNING - Failed bootstrap phase; try=1 max_retries=-1
telegram.vendor.ptb_urllib3.urllib3.connectionpool - WARNING - Retrying (Retry(total=2, connect=None, read=None, redirect=None)) after connection broken by 'NewConnectionError('<telegram.vendor.ptb_urllib3.urllib3.contrib.socks.SOCKSHTTPSConnection object at 0x10c848c88>: Failed to establish a new connection: 0x02: Connection not allowed by ruleset')': /bot883704044:AAEgGQKBqM-5tOQnApLj--n-T7Hhub8OL4w/deleteWebhook
telegram.vendor.ptb_urllib3.urllib3.connectionpool - WARNING - Retrying (Retry(total=1, connect=None, read=None, redirect=None)) after connection broken by 'NewConnectionError('<telegram.vendor.ptb_urllib3.urllib3.contrib.socks.SOCKSHTTPSConnection object at 0x10c866160>: Failed to establish a new connection: 0x02: Connection not allowed by ruleset')': /bot883704044:AAEgGQKBqM-5tOQnApLj--n-T7Hhub8OL4w/deleteWebhook
telegram.vendor.ptb_urllib3.urllib3.connectionpool - WARNING - Retrying (Retry(total=0, connect=None, read=None, redirect=None)) after connection broken by 'NewConnectionError('<telegram.vendor.ptb_urllib3.urllib3.contrib.socks.SOCKSHTTPSConnection object at 0x10c848ac8>: Failed to establish a new connection: 0x02: Connection not allowed by ruleset')': /bot883704044:AAEgGQKBqM-5tOQnApLj--n-T7Hhub8OL4w/deleteWebhook
telegram.ext.updater - ERROR - Error while bootstrap del webhook: urllib3 HTTPError SOCKSHTTPSConnectionPool(host='api.telegram.org', port=443): Max retries exceeded with url: /bot883704044:AAEgGQKBqM-5tOQnApLj--n-T7Hhub8OL4w/deleteWebhook (Caused by NewConnectionError('<telegram.vendor.ptb_urllib3.urllib3.contrib.socks.SOCKSHTTPSConnection object at 0x10c848f28>: Failed to establish a new connection: 0x02: Connection not allowed by ruleset'))
telegram.ext.updater - WARNING - Failed bootstrap phase; try=2 max_retries=-1
telegram.vendor.ptb_urllib3.urllib3.connectionpool - WARNING - Retrying (Retry(total=2, connect=None, read=None, redirect=None)) after connection broken by 'NewConnectionError('<telegram.vendor.ptb_urllib3.urllib3.contrib.socks.SOCKSHTTPSConnection object at 0x10c848e80>: Failed to establish a new connection: 0x02: Connection not allowed by ruleset')': /bot883704044:AAEgGQKBqM-5tOQnApLj--n-T7Hhub8OL4w/deleteWebhook
telegram.vendor.ptb_urllib3.urllib3.connectionpool - WARNING - Retrying (Retry(total=1, connect=None, read=None, redirect=None)) after connection broken by 'NewConnectionError('<telegram.vendor.ptb_urllib3.urllib3.contrib.socks.SOCKSHTTPSConnection object at 0x10c83b630>: Failed to establish a new connection: 0x02: Connection not allowed by ruleset')': /bot883704044:AAEgGQKBqM-5tOQnApLj--n-T7Hhub8OL4w/deleteWebhook
telegram.vendor.ptb_urllib3.urllib3.connectionpool - WARNING - Retrying (Retry(total=0, connect=None, read=None, redirect=None)) after connection broken by 'NewConnectionError('<telegram.vendor.ptb_urllib3.urllib3.contrib.socks.SOCKSHTTPSConnection object at 0x10c866208>: Failed to establish a new connection: 0x02: Connection not allowed by ruleset')': /bot883704044:AAEgGQKBqM-5tOQnApLj--n-T7Hhub8OL4w/deleteWebhook
telegram.ext.updater - ERROR - Error while bootstrap del webhook: urllib3 HTTPError SOCKSHTTPSConnectionPool(host='api.telegram.org', port=443): Max retries exceeded with url: /bot883704044:AAEgGQKBqM-5tOQnApLj--n-T7Hhub8OL4w/deleteWebhook (Caused by NewConnectionError('<telegram.vendor.ptb_urllib3.urllib3.contrib.socks.SOCKSHTTPSConnection object at 0x10c866400>: Failed to establish a new connection: 0x02: Connection not allowed by ruleset'))
telegram.ext.updater - WARNING - Failed bootstrap phase; try=3 max_retries=-1
telegram.vendor.ptb_urllib3.urllib3.connectionpool - WARNING - Retrying (Retry(total=2, connect=None, read=None, redirect=None)) after connection broken by 'NewConnectionError('<telegram.vendor.ptb_urllib3.urllib3.contrib.socks.SOCKSHTTPSConnection object at 0x10c8664a8>: Failed to establish a new connection: 0x02: Connection not allowed by ruleset')': /bot883704044:AAEgGQKBqM-5tOQnApLj--n-T7Hhub8OL4w/deleteWebhook
telegram.vendor.ptb_urllib3.urllib3.connectionpool - WARNING - Retrying (Retry(total=1, connect=None, read=None, redirect=None)) after connection broken by 'NewConnectionError('<telegram.vendor.ptb_urllib3.urllib3.contrib.socks.SOCKSHTTPSConnection object at 0x10c866908>: Failed to establish a new connection: 0x02: Connection not allowed by ruleset')': /bot883704044:AAEgGQKBqM-5tOQnApLj--n-T7Hhub8OL4w/deleteWebhook
telegram.vendor.ptb_urllib3.urllib3.connectionpool - WARNING - Retrying (Retry(total=0, connect=None, read=None, redirect=None)) after connection broken by 'NewConnectionError('<telegram.vendor.ptb_urllib3.urllib3.contrib.socks.SOCKSHTTPSConnection object at 0x10c8669b0>: Failed to establish a new connection: 0x02: Connection not allowed by ruleset')': /bot883704044:AAEgGQKBqM-5tOQnApLj--n-T7Hhub8OL4w/deleteWebhook
telegram.ext.updater - ERROR - Error while bootstrap del webhook: urllib3 HTTPError SOCKSHTTPSConnectionPool(host='api.telegram.org', port=443): Max retries exceeded with url: /bot883704044:AAEgGQKBqM-5tOQnApLj--n-T7Hhub8OL4w/deleteWebhook (Caused by NewConnectionError('<telegram.vendor.ptb_urllib3.urllib3.contrib.socks.SOCKSHTTPSConnection object at 0x10c866ba8>: Failed to establish a new connection: 0x02: Connection not allowed by ruleset'))
telegram.ext.updater - WARNING - Failed bootstrap phase; try=4 max_retries=-1
telegram.vendor.ptb_urllib3.urllib3.connectionpool - WARNING - Retrying (Retry(total=2, connect=None, read=None, redirect=None)) after connection broken by 'NewConnectionError('<telegram.vendor.ptb_urllib3.urllib3.contrib.socks.SOCKSHTTPSConnection object at 0x10c866668>: Failed to establish a new connection: 0x02: Connection not allowed by ruleset')': /bot883704044:AAEgGQKBqM-5tOQnApLj--n-T7Hhub8OL4w/deleteWebhook
telegram.vendor.ptb_urllib3.urllib3.connectionpool - WARNING - Retrying (Retry(total=1, connect=None, read=None, redirect=None)) after connection broken by 'NewConnectionError('<telegram.vendor.ptb_urllib3.urllib3.contrib.socks.SOCKSHTTPSConnection object at 0x10c9b7160>: Failed to establish a new connection: 0x02: Connection not allowed by ruleset')': /bot883704044:AAEgGQKBqM-5tOQnApLj--n-T7Hhub8OL4w/deleteWebhook
telegram.vendor.ptb_urllib3.urllib3.connectionpool - WARNING - Retrying (Retry(total=0, connect=None, read=None, redirect=None)) after connection broken by 'NewConnectionError('<telegram.vendor.ptb_urllib3.urllib3.contrib.socks.SOCKSHTTPSConnection object at 0x10c9b7208>: Failed to establish a new connection: 0x02: Connection not allowed by ruleset')': /bot883704044:AAEgGQKBqM-5tOQnApLj--n-T7Hhub8OL4w/deleteWebhook
telegram.ext.updater - ERROR - Error while bootstrap del webhook: urllib3 HTTPError SOCKSHTTPSConnectionPool(host='api.telegram.org', port=443): Max retries exceeded with url: /bot883704044:AAEgGQKBqM-5tOQnApLj--n-T7Hhub8OL4w/deleteWebhook (Caused by NewConnectionError('<telegram.vendor.ptb_urllib3.urllib3.contrib.socks.SOCKSHTTPSConnection object at 0x10c83b0b8>: Failed to establish a new connection: 0x02: Connection not allowed by ruleset'))
telegram.ext.updater - WARNING - Failed bootstrap phase; try=5 max_retries=-1
telegram.ext.updater - INFO - Received signal 2 (SIGINT), stopping...
telegram.ext.updater - WARNING - Exiting immediately!
telegram.ext.dispatcher - ERROR - An uncaught error was raised while processing the update
Traceback (most recent call last):
  File "/Users/nermohin/anaconda3/lib/python3.7/site-packages/telegram/ext/dispatcher.py", line 279, in process_update
    handler.handle_update(update, self)
  File "/Users/nermohin/anaconda3/lib/python3.7/site-packages/telegram/ext/commandhandler.py", line 173, in handle_update
    return self.callback(dispatcher.bot, update, **optional_args)
  File "bot.py", line 16, in greet_user
    update.message.reply_text(f'Привет {update.message.first_name}')
AttributeError: 'Message' object has no attribute 'first_name'
telegram.ext.dispatcher - ERROR - An uncaught error was raised while processing the update
Traceback (most recent call last):
  File "/Users/nermohin/anaconda3/lib/python3.7/site-packages/telegram/ext/dispatcher.py", line 279, in process_update
    handler.handle_update(update, self)
  File "/Users/nermohin/anaconda3/lib/python3.7/site-packages/telegram/ext/commandhandler.py", line 173, in handle_update
    return self.callback(dispatcher.bot, update, **optional_args)
  File "bot.py", line 16, in greet_user
    update.message.reply_text(f'Привет {update.message.first_name}')
AttributeError: 'Message' object has no attribute 'first_name'
telegram.ext.dispatcher - ERROR - An uncaught error was raised while processing the update
Traceback (most recent call last):
  File "/Users/nermohin/anaconda3/lib/python3.7/site-packages/telegram/ext/dispatcher.py", line 279, in process_update
    handler.handle_update(update, self)
  File "/Users/nermohin/anaconda3/lib/python3.7/site-packages/telegram/ext/commandhandler.py", line 173, in handle_update
    return self.callback(dispatcher.bot, update, **optional_args)
  File "bot.py", line 16, in greet_user
    update.message.reply_text(f'Привет {update.message.first_name}')
AttributeError: 'Message' object has no attribute 'first_name'
telegram.ext.dispatcher - ERROR - An uncaught error was raised while processing the update
Traceback (most recent call last):
  File "/Users/nermohin/anaconda3/lib/python3.7/site-packages/telegram/ext/dispatcher.py", line 279, in process_update
    handler.handle_update(update, self)
  File "/Users/nermohin/anaconda3/lib/python3.7/site-packages/telegram/ext/commandhandler.py", line 173, in handle_update
    return self.callback(dispatcher.bot, update, **optional_args)
  File "bot.py", line 16, in greet_user
    update.message.reply_text(f'Привет {update.message.first_name}')
AttributeError: 'Message' object has no attribute 'first_name'
telegram.ext.dispatcher - ERROR - An uncaught error was raised while processing the update
Traceback (most recent call last):
  File "/Users/nermohin/anaconda3/lib/python3.7/site-packages/telegram/ext/dispatcher.py", line 279, in process_update
    handler.handle_update(update, self)
  File "/Users/nermohin/anaconda3/lib/python3.7/site-packages/telegram/ext/commandhandler.py", line 173, in handle_update
    return self.callback(dispatcher.bot, update, **optional_args)
  File "bot.py", line 16, in greet_user
    update.message.reply_text(f'Привет {update.message.first_name}')
AttributeError: 'Message' object has no attribute 'first_name'
telegram.ext.dispatcher - ERROR - An uncaught error was raised while processing the update
Traceback (most recent call last):
  File "/Users/nermohin/anaconda3/lib/python3.7/site-packages/telegram/ext/dispatcher.py", line 279, in process_update
    handler.handle_update(update, self)
  File "/Users/nermohin/anaconda3/lib/python3.7/site-packages/telegram/ext/commandhandler.py", line 173, in handle_update
    return self.callback(dispatcher.bot, update, **optional_args)
  File "bot.py", line 16, in greet_user
    update.message.reply_text(f'Привет {update.message.first_name}')
AttributeError: 'Message' object has no attribute 'first_name'
telegram.ext.dispatcher - ERROR - An uncaught error was raised while processing the update
Traceback (most recent call last):
  File "/Users/nermohin/anaconda3/lib/python3.7/site-packages/telegram/ext/dispatcher.py", line 279, in process_update
    handler.handle_update(update, self)
  File "/Users/nermohin/anaconda3/lib/python3.7/site-packages/telegram/ext/commandhandler.py", line 173, in handle_update
    return self.callback(dispatcher.bot, update, **optional_args)
  File "bot.py", line 16, in greet_user
    update.message.reply_text(f'Привет {update.message.first_name}')
AttributeError: 'Message' object has no attribute 'first_name'
telegram.ext.dispatcher - ERROR - An uncaught error was raised while processing the update
Traceback (most recent call last):
  File "/Users/nermohin/anaconda3/lib/python3.7/site-packages/telegram/ext/dispatcher.py", line 279, in process_update
    handler.handle_update(update, self)
  File "/Users/nermohin/anaconda3/lib/python3.7/site-packages/telegram/ext/commandhandler.py", line 173, in handle_update
    return self.callback(dispatcher.bot, update, **optional_args)
  File "bot.py", line 16, in greet_user
    update.message.reply_text(f'Привет {update.message.first_name}')
AttributeError: 'Message' object has no attribute 'first_name'
telegram.ext.dispatcher - ERROR - An uncaught error was raised while processing the update
Traceback (most recent call last):
  File "/Users/nermohin/anaconda3/lib/python3.7/site-packages/telegram/ext/dispatcher.py", line 279, in process_update
    handler.handle_update(update, self)
  File "/Users/nermohin/anaconda3/lib/python3.7/site-packages/telegram/ext/commandhandler.py", line 173, in handle_update
    return self.callback(dispatcher.bot, update, **optional_args)
  File "bot.py", line 16, in greet_user
    update.message.reply_text(f'Привет {update.message.first_name}')
AttributeError: 'Message' object has no attribute 'first_name'
telegram.ext.updater - INFO - Received signal 2 (SIGINT), stopping...
telegram.ext.dispatcher - ERROR - An uncaught error was raised while processing the update
Traceback (most recent call last):
  File "/Users/nermohin/anaconda3/lib/python3.7/site-packages/telegram/ext/dispatcher.py", line 279, in process_update
    handler.handle_update(update, self)
  File "/Users/nermohin/anaconda3/lib/python3.7/site-packages/telegram/ext/commandhandler.py", line 173, in handle_update
    return self.callback(dispatcher.bot, update, **optional_args)
  File "bot.py", line 16, in greet_user
    update.message.reply_text(f'Привет {update.message.form.first_name}')
AttributeError: 'Message' object has no attribute 'form'
telegram.ext.dispatcher - ERROR - An uncaught error was raised while processing the update
Traceback (most recent call last):
  File "/Users/nermohin/anaconda3/lib/python3.7/site-packages/telegram/ext/dispatcher.py", line 279, in process_update
    handler.handle_update(update, self)
  File "/Users/nermohin/anaconda3/lib/python3.7/site-packages/telegram/ext/commandhandler.py", line 173, in handle_update
    return self.callback(dispatcher.bot, update, **optional_args)
  File "bot.py", line 16, in greet_user
    update.message.reply_text(f'Привет {update.message.form.first_name}')
AttributeError: 'Message' object has no attribute 'form'
telegram.ext.updater - INFO - Received signal 2 (SIGINT), stopping...
telegram.ext.dispatcher - ERROR - An uncaught error was raised while processing the update
Traceback (most recent call last):
  File "/Users/nermohin/anaconda3/lib/python3.7/site-packages/telegram/ext/dispatcher.py", line 279, in process_update
    handler.handle_update(update, self)
  File "/Users/nermohin/anaconda3/lib/python3.7/site-packages/telegram/ext/commandhandler.py", line 173, in handle_update
    return self.callback(dispatcher.bot, update, **optional_args)
  File "bot.py", line 14, in greet_user
    text = str(update.message.form.first_name)
AttributeError: 'Message' object has no attribute 'form'
telegram.ext.dispatcher - ERROR - An uncaught error was raised while processing the update
Traceback (most recent call last):
  File "/Users/nermohin/anaconda3/lib/python3.7/site-packages/telegram/ext/dispatcher.py", line 279, in process_update
    handler.handle_update(update, self)
  File "/Users/nermohin/anaconda3/lib/python3.7/site-packages/telegram/ext/commandhandler.py", line 173, in handle_update
    return self.callback(dispatcher.bot, update, **optional_args)
  File "bot.py", line 14, in greet_user
    text = str(update.message.form.first_name)
AttributeError: 'Message' object has no attribute 'form'
telegram.ext.dispatcher - ERROR - An uncaught error was raised while processing the update
Traceback (most recent call last):
  File "/Users/nermohin/anaconda3/lib/python3.7/site-packages/telegram/ext/dispatcher.py", line 279, in process_update
    handler.handle_update(update, self)
  File "/Users/nermohin/anaconda3/lib/python3.7/site-packages/telegram/ext/commandhandler.py", line 173, in handle_update
    return self.callback(dispatcher.bot, update, **optional_args)
  File "bot.py", line 14, in greet_user
    text = str(update.message.form.first_name)
AttributeError: 'Message' object has no attribute 'form'
telegram.ext.updater - INFO - Received signal 2 (SIGINT), stopping...
telegram.ext.dispatcher - ERROR - An uncaught error was raised while processing the update
Traceback (most recent call last):
  File "/Users/nermohin/anaconda3/lib/python3.7/site-packages/telegram/ext/dispatcher.py", line 279, in process_update
    handler.handle_update(update, self)
  File "/Users/nermohin/anaconda3/lib/python3.7/site-packages/telegram/ext/commandhandler.py", line 173, in handle_update
    return self.callback(dispatcher.bot, update, **optional_args)
  File "bot.py", line 14, in greet_user
    text = str(update.message.form.first_name)
AttributeError: 'Message' object has no attribute 'form'
telegram.ext.dispatcher - ERROR - An uncaught error was raised while processing the update
Traceback (most recent call last):
  File "/Users/nermohin/anaconda3/lib/python3.7/site-packages/telegram/ext/dispatcher.py", line 279, in process_update
    handler.handle_update(update, self)
  File "/Users/nermohin/anaconda3/lib/python3.7/site-packages/telegram/ext/commandhandler.py", line 173, in handle_update
    return self.callback(dispatcher.bot, update, **optional_args)
  File "bot.py", line 14, in greet_user
    text = str(update.message.form.first_name)
AttributeError: 'Message' object has no attribute 'form'
telegram.ext.updater - INFO - Received signal 2 (SIGINT), stopping...
telegram.ext.dispatcher - ERROR - An uncaught error was raised while processing the update
Traceback (most recent call last):
  File "/Users/nermohin/anaconda3/lib/python3.7/site-packages/telegram/ext/dispatcher.py", line 279, in process_update
    handler.handle_update(update, self)
  File "/Users/nermohin/anaconda3/lib/python3.7/site-packages/telegram/ext/commandhandler.py", line 173, in handle_update
    return self.callback(dispatcher.bot, update, **optional_args)
  File "bot.py", line 14, in greet_user
    text = str(update.message.User.first_name)
AttributeError: 'Message' object has no attribute 'User'
telegram.ext.updater - INFO - Received signal 2 (SIGINT), stopping...
telegram.ext.dispatcher - ERROR - An uncaught error was raised while processing the update
Traceback (most recent call last):
  File "/Users/nermohin/anaconda3/lib/python3.7/site-packages/telegram/ext/dispatcher.py", line 279, in process_update
    handler.handle_update(update, self)
  File "/Users/nermohin/anaconda3/lib/python3.7/site-packages/telegram/ext/commandhandler.py", line 173, in handle_update
    return self.callback(dispatcher.bot, update, **optional_args)
  File "bot.py", line 14, in greet_user
    text = str(update.message.fromUser.first_name)
AttributeError: 'Message' object has no attribute 'fromUser'
telegram.ext.updater - INFO - Received signal 2 (SIGINT), stopping...
telegram.ext.updater - INFO - Received signal 2 (SIGINT), stopping...
telegram.ext.updater - INFO - Received signal 2 (SIGINT), stopping...
telegram.ext.updater - INFO - Received signal 2 (SIGINT), stopping...
telegram.ext.updater - INFO - Received signal 2 (SIGINT), stopping...
telegram.ext.updater - INFO - Received signal 2 (SIGINT), stopping...
telegram.ext.updater - INFO - Received signal 2 (SIGINT), stopping...
telegram.ext.dispatcher - ERROR - An uncaught error was raised while processing the update
Traceback (most recent call last):
  File "/Users/nermohin/anaconda3/lib/python3.7/site-packages/telegram/ext/dispatcher.py", line 278, in process_update
    for handler in (x for x in self.handlers[group] if x.check_update(update)):
  File "/Users/nermohin/anaconda3/lib/python3.7/site-packages/telegram/ext/dispatcher.py", line 278, in <genexpr>
    for handler in (x for x in self.handlers[group] if x.check_update(update)):
  File "/Users/nermohin/anaconda3/lib/python3.7/site-packages/telegram/ext/messagehandler.py", line 152, in check_update
    res = self.filters(message)
TypeError: 'str' object is not callable
telegram.ext.dispatcher - ERROR - An uncaught error was raised while processing the update
Traceback (most recent call last):
  File "/Users/nermohin/anaconda3/lib/python3.7/site-packages/telegram/ext/dispatcher.py", line 278, in process_update
    for handler in (x for x in self.handlers[group] if x.check_update(update)):
  File "/Users/nermohin/anaconda3/lib/python3.7/site-packages/telegram/ext/dispatcher.py", line 278, in <genexpr>
    for handler in (x for x in self.handlers[group] if x.check_update(update)):
  File "/Users/nermohin/anaconda3/lib/python3.7/site-packages/telegram/ext/messagehandler.py", line 152, in check_update
    res = self.filters(message)
TypeError: 'str' object is not callable
telegram.ext.dispatcher - ERROR - An uncaught error was raised while processing the update
Traceback (most recent call last):
  File "/Users/nermohin/anaconda3/lib/python3.7/site-packages/telegram/ext/dispatcher.py", line 278, in process_update
    for handler in (x for x in self.handlers[group] if x.check_update(update)):
  File "/Users/nermohin/anaconda3/lib/python3.7/site-packages/telegram/ext/dispatcher.py", line 278, in <genexpr>
    for handler in (x for x in self.handlers[group] if x.check_update(update)):
  File "/Users/nermohin/anaconda3/lib/python3.7/site-packages/telegram/ext/messagehandler.py", line 152, in check_update
    res = self.filters(message)
TypeError: 'str' object is not callable
telegram.ext.dispatcher - ERROR - An uncaught error was raised while processing the update
Traceback (most recent call last):
  File "/Users/nermohin/anaconda3/lib/python3.7/site-packages/telegram/ext/dispatcher.py", line 278, in process_update
    for handler in (x for x in self.handlers[group] if x.check_update(update)):
  File "/Users/nermohin/anaconda3/lib/python3.7/site-packages/telegram/ext/dispatcher.py", line 278, in <genexpr>
    for handler in (x for x in self.handlers[group] if x.check_update(update)):
  File "/Users/nermohin/anaconda3/lib/python3.7/site-packages/telegram/ext/messagehandler.py", line 152, in check_update
    res = self.filters(message)
TypeError: 'str' object is not callable
telegram.ext.updater - INFO - Received signal 2 (SIGINT), stopping...
telegram.ext.updater - INFO - Received signal 2 (SIGINT), stopping...
telegram.ext.updater - INFO - Received signal 2 (SIGINT), stopping...
telegram.vendor.ptb_urllib3.urllib3.connectionpool - WARNING - Retrying (Retry(total=2, connect=None, read=None, redirect=None)) after connection broken by 'NewConnectionError('<telegram.vendor.ptb_urllib3.urllib3.connection.VerifiedHTTPSConnection object at 0x1072636a0>: Failed to establish a new connection: [Errno 61] Connection refused')': /bot883704044:AAEgGQKBqM-5tOQnApLj--n-T7Hhub8OL4w/deleteWebhook
telegram.vendor.ptb_urllib3.urllib3.connectionpool - WARNING - Retrying (Retry(total=1, connect=None, read=None, redirect=None)) after connection broken by 'NewConnectionError('<telegram.vendor.ptb_urllib3.urllib3.connection.VerifiedHTTPSConnection object at 0x1072637b8>: Failed to establish a new connection: [Errno 61] Connection refused')': /bot883704044:AAEgGQKBqM-5tOQnApLj--n-T7Hhub8OL4w/deleteWebhook
telegram.vendor.ptb_urllib3.urllib3.connectionpool - WARNING - Retrying (Retry(total=0, connect=None, read=None, redirect=None)) after connection broken by 'NewConnectionError('<telegram.vendor.ptb_urllib3.urllib3.connection.VerifiedHTTPSConnection object at 0x107263d68>: Failed to establish a new connection: [Errno 61] Connection refused')': /bot883704044:AAEgGQKBqM-5tOQnApLj--n-T7Hhub8OL4w/deleteWebhook
telegram.ext.updater - ERROR - Error while bootstrap del webhook: urllib3 HTTPError HTTPSConnectionPool(host='api.telegram.org', port=443): Max retries exceeded with url: /bot883704044:AAEgGQKBqM-5tOQnApLj--n-T7Hhub8OL4w/deleteWebhook (Caused by NewConnectionError('<telegram.vendor.ptb_urllib3.urllib3.connection.VerifiedHTTPSConnection object at 0x1072638d0>: Failed to establish a new connection: [Errno 61] Connection refused'))
telegram.ext.updater - WARNING - Failed bootstrap phase; try=1 max_retries=-1
telegram.vendor.ptb_urllib3.urllib3.connectionpool - WARNING - Retrying (Retry(total=2, connect=None, read=None, redirect=None)) after connection broken by 'NewConnectionError('<telegram.vendor.ptb_urllib3.urllib3.connection.VerifiedHTTPSConnection object at 0x1072812e8>: Failed to establish a new connection: [Errno 61] Connection refused')': /bot883704044:AAEgGQKBqM-5tOQnApLj--n-T7Hhub8OL4w/deleteWebhook
telegram.vendor.ptb_urllib3.urllib3.connectionpool - WARNING - Retrying (Retry(total=1, connect=None, read=None, redirect=None)) after connection broken by 'NewConnectionError('<telegram.vendor.ptb_urllib3.urllib3.connection.VerifiedHTTPSConnection object at 0x107281438>: Failed to establish a new connection: [Errno 61] Connection refused')': /bot883704044:AAEgGQKBqM-5tOQnApLj--n-T7Hhub8OL4w/deleteWebhook
telegram.vendor.ptb_urllib3.urllib3.connectionpool - WARNING - Retrying (Retry(total=0, connect=None, read=None, redirect=None)) after connection broken by 'NewConnectionError('<telegram.vendor.ptb_urllib3.urllib3.connection.VerifiedHTTPSConnection object at 0x1072814e0>: Failed to establish a new connection: [Errno 61] Connection refused')': /bot883704044:AAEgGQKBqM-5tOQnApLj--n-T7Hhub8OL4w/deleteWebhook
telegram.ext.updater - ERROR - Error while bootstrap del webhook: urllib3 HTTPError HTTPSConnectionPool(host='api.telegram.org', port=443): Max retries exceeded with url: /bot883704044:AAEgGQKBqM-5tOQnApLj--n-T7Hhub8OL4w/deleteWebhook (Caused by NewConnectionError('<telegram.vendor.ptb_urllib3.urllib3.connection.VerifiedHTTPSConnection object at 0x1072815c0>: Failed to establish a new connection: [Errno 61] Connection refused'))
telegram.ext.updater - WARNING - Failed bootstrap phase; try=2 max_retries=-1
telegram.vendor.ptb_urllib3.urllib3.connectionpool - WARNING - Retrying (Retry(total=2, connect=None, read=None, redirect=None)) after connection broken by 'NewConnectionError('<telegram.vendor.ptb_urllib3.urllib3.connection.VerifiedHTTPSConnection object at 0x107281390>: Failed to establish a new connection: [Errno 61] Connection refused')': /bot883704044:AAEgGQKBqM-5tOQnApLj--n-T7Hhub8OL4w/deleteWebhook
telegram.vendor.ptb_urllib3.urllib3.connectionpool - WARNING - Retrying (Retry(total=1, connect=None, read=None, redirect=None)) after connection broken by 'NewConnectionError('<telegram.vendor.ptb_urllib3.urllib3.connection.VerifiedHTTPSConnection object at 0x1072818d0>: Failed to establish a new connection: [Errno 61] Connection refused')': /bot883704044:AAEgGQKBqM-5tOQnApLj--n-T7Hhub8OL4w/deleteWebhook
telegram.vendor.ptb_urllib3.urllib3.connectionpool - WARNING - Retrying (Retry(total=0, connect=None, read=None, redirect=None)) after connection broken by 'NewConnectionError('<telegram.vendor.ptb_urllib3.urllib3.connection.VerifiedHTTPSConnection object at 0x107281978>: Failed to establish a new connection: [Errno 61] Connection refused')': /bot883704044:AAEgGQKBqM-5tOQnApLj--n-T7Hhub8OL4w/deleteWebhook
telegram.ext.updater - ERROR - Error while bootstrap del webhook: urllib3 HTTPError HTTPSConnectionPool(host='api.telegram.org', port=443): Max retries exceeded with url: /bot883704044:AAEgGQKBqM-5tOQnApLj--n-T7Hhub8OL4w/deleteWebhook (Caused by NewConnectionError('<telegram.vendor.ptb_urllib3.urllib3.connection.VerifiedHTTPSConnection object at 0x107281a58>: Failed to establish a new connection: [Errno 61] Connection refused'))
telegram.ext.updater - WARNING - Failed bootstrap phase; try=3 max_retries=-1
telegram.vendor.ptb_urllib3.urllib3.connectionpool - WARNING - Retrying (Retry(total=2, connect=None, read=None, redirect=None)) after connection broken by 'NewConnectionError('<telegram.vendor.ptb_urllib3.urllib3.connection.VerifiedHTTPSConnection object at 0x107281828>: Failed to establish a new connection: [Errno 61] Connection refused')': /bot883704044:AAEgGQKBqM-5tOQnApLj--n-T7Hhub8OL4w/deleteWebhook
telegram.vendor.ptb_urllib3.urllib3.connectionpool - WARNING - Retrying (Retry(total=1, connect=None, read=None, redirect=None)) after connection broken by 'NewConnectionError('<telegram.vendor.ptb_urllib3.urllib3.connection.VerifiedHTTPSConnection object at 0x107281d68>: Failed to establish a new connection: [Errno 61] Connection refused')': /bot883704044:AAEgGQKBqM-5tOQnApLj--n-T7Hhub8OL4w/deleteWebhook
telegram.vendor.ptb_urllib3.urllib3.connectionpool - WARNING - Retrying (Retry(total=0, connect=None, read=None, redirect=None)) after connection broken by 'NewConnectionError('<telegram.vendor.ptb_urllib3.urllib3.connection.VerifiedHTTPSConnection object at 0x1072634e0>: Failed to establish a new connection: [Errno 61] Connection refused')': /bot883704044:AAEgGQKBqM-5tOQnApLj--n-T7Hhub8OL4w/deleteWebhook
telegram.ext.updater - ERROR - Error while bootstrap del webhook: urllib3 HTTPError HTTPSConnectionPool(host='api.telegram.org', port=443): Max retries exceeded with url: /bot883704044:AAEgGQKBqM-5tOQnApLj--n-T7Hhub8OL4w/deleteWebhook (Caused by NewConnectionError('<telegram.vendor.ptb_urllib3.urllib3.connection.VerifiedHTTPSConnection object at 0x1072634a8>: Failed to establish a new connection: [Errno 61] Connection refused'))
telegram.ext.updater - WARNING - Failed bootstrap phase; try=4 max_retries=-1
telegram.vendor.ptb_urllib3.urllib3.connectionpool - WARNING - Retrying (Retry(total=2, connect=None, read=None, redirect=None)) after connection broken by 'NewConnectionError('<telegram.vendor.ptb_urllib3.urllib3.connection.VerifiedHTTPSConnection object at 0x107263d68>: Failed to establish a new connection: [Errno 61] Connection refused')': /bot883704044:AAEgGQKBqM-5tOQnApLj--n-T7Hhub8OL4w/deleteWebhook
telegram.vendor.ptb_urllib3.urllib3.connectionpool - WARNING - Retrying (Retry(total=1, connect=None, read=None, redirect=None)) after connection broken by 'NewConnectionError('<telegram.vendor.ptb_urllib3.urllib3.connection.VerifiedHTTPSConnection object at 0x1072636d8>: Failed to establish a new connection: [Errno 61] Connection refused')': /bot883704044:AAEgGQKBqM-5tOQnApLj--n-T7Hhub8OL4w/deleteWebhook
telegram.vendor.ptb_urllib3.urllib3.connectionpool - WARNING - Retrying (Retry(total=0, connect=None, read=None, redirect=None)) after connection broken by 'NewConnectionError('<telegram.vendor.ptb_urllib3.urllib3.connection.VerifiedHTTPSConnection object at 0x107281710>: Failed to establish a new connection: [Errno 61] Connection refused')': /bot883704044:AAEgGQKBqM-5tOQnApLj--n-T7Hhub8OL4w/deleteWebhook
telegram.ext.updater - ERROR - Error while bootstrap del webhook: urllib3 HTTPError HTTPSConnectionPool(host='api.telegram.org', port=443): Max retries exceeded with url: /bot883704044:AAEgGQKBqM-5tOQnApLj--n-T7Hhub8OL4w/deleteWebhook (Caused by NewConnectionError('<telegram.vendor.ptb_urllib3.urllib3.connection.VerifiedHTTPSConnection object at 0x107281908>: Failed to establish a new connection: [Errno 61] Connection refused'))
telegram.ext.updater - WARNING - Failed bootstrap phase; try=5 max_retries=-1
telegram.ext.updater - INFO - Received signal 2 (SIGINT), stopping...
telegram.ext.updater - INFO - Received signal 2 (SIGINT), stopping...
telegram.ext.updater - WARNING - Exiting immediately!
telegram.ext.updater - INFO - Received signal 2 (SIGINT), stopping...
telegram.ext.dispatcher - ERROR - An uncaught error was raised while processing the update
Traceback (most recent call last):
  File "/Users/nermohin/anaconda3/lib/python3.7/site-packages/telegram/ext/dispatcher.py", line 279, in process_update
    handler.handle_update(update, self)
  File "/Users/nermohin/anaconda3/lib/python3.7/site-packages/telegram/ext/commandhandler.py", line 173, in handle_update
    return self.callback(dispatcher.bot, update, **optional_args)
  File "bot.py", line 19, in planet_position
    print(user_text[1])
IndexError: list index out of range
telegram.ext.updater - INFO - Received signal 2 (SIGINT), stopping...
telegram.ext.dispatcher - ERROR - An uncaught error was raised while processing the update
Traceback (most recent call last):
  File "/Users/nermohin/anaconda3/lib/python3.7/site-packages/telegram/ext/dispatcher.py", line 279, in process_update
    handler.handle_update(update, self)
  File "/Users/nermohin/anaconda3/lib/python3.7/site-packages/telegram/ext/commandhandler.py", line 173, in handle_update
    return self.callback(dispatcher.bot, update, **optional_args)
  File "bot.py", line 21, in planet_position
    update.message.reply_text(ephem.constellation(input_planet))
ValueError: the sequence specifying a position must have exactly two coordinates
telegram.ext.dispatcher - ERROR - An uncaught error was raised while processing the update
Traceback (most recent call last):
  File "/Users/nermohin/anaconda3/lib/python3.7/site-packages/telegram/ext/dispatcher.py", line 279, in process_update
    handler.handle_update(update, self)
  File "/Users/nermohin/anaconda3/lib/python3.7/site-packages/telegram/ext/commandhandler.py", line 173, in handle_update
    return self.callback(dispatcher.bot, update, **optional_args)
  File "bot.py", line 20, in planet_position
    input_planet = (user_text[1])
IndexError: list index out of range
telegram.ext.updater - INFO - Received signal 2 (SIGINT), stopping...
telegram.ext.dispatcher - ERROR - An uncaught error was raised while processing the update
Traceback (most recent call last):
  File "/Users/nermohin/anaconda3/lib/python3.7/site-packages/telegram/ext/dispatcher.py", line 279, in process_update
    handler.handle_update(update, self)
  File "/Users/nermohin/anaconda3/lib/python3.7/site-packages/telegram/ext/commandhandler.py", line 173, in handle_update
    return self.callback(dispatcher.bot, update, **optional_args)
  File "bot.py", line 21, in planet_position
    print(ephem.constellation(input_planet))
ValueError: the sequence specifying a position must have exactly two coordinates
telegram.ext.dispatcher - ERROR - An uncaught error was raised while processing the update
Traceback (most recent call last):
  File "/Users/nermohin/anaconda3/lib/python3.7/site-packages/telegram/ext/dispatcher.py", line 279, in process_update
    handler.handle_update(update, self)
  File "/Users/nermohin/anaconda3/lib/python3.7/site-packages/telegram/ext/commandhandler.py", line 173, in handle_update
    return self.callback(dispatcher.bot, update, **optional_args)
  File "bot.py", line 20, in planet_position
    input_planet = (user_text[1])
IndexError: list index out of range
telegram.ext.dispatcher - ERROR - An uncaught error was raised while processing the update
Traceback (most recent call last):
  File "/Users/nermohin/anaconda3/lib/python3.7/site-packages/telegram/ext/dispatcher.py", line 279, in process_update
    handler.handle_update(update, self)
  File "/Users/nermohin/anaconda3/lib/python3.7/site-packages/telegram/ext/commandhandler.py", line 173, in handle_update
    return self.callback(dispatcher.bot, update, **optional_args)
  File "bot.py", line 20, in planet_position
    input_planet = (user_text[1])
IndexError: list index out of range
telegram.ext.dispatcher - ERROR - An uncaught error was raised while processing the update
Traceback (most recent call last):
  File "/Users/nermohin/anaconda3/lib/python3.7/site-packages/telegram/ext/dispatcher.py", line 279, in process_update
    handler.handle_update(update, self)
  File "/Users/nermohin/anaconda3/lib/python3.7/site-packages/telegram/ext/commandhandler.py", line 173, in handle_update
    return self.callback(dispatcher.bot, update, **optional_args)
  File "bot.py", line 21, in planet_position
    print(ephem.constellation(input_planet))
ValueError: the sequence specifying a position must have exactly two coordinates
telegram.ext.updater - INFO - Received signal 2 (SIGINT), stopping...
telegram.ext.updater - INFO - Received signal 2 (SIGINT), stopping...
telegram.ext.dispatcher - ERROR - An uncaught error was raised while processing the update
Traceback (most recent call last):
  File "/Users/nermohin/anaconda3/lib/python3.7/site-packages/telegram/ext/dispatcher.py", line 279, in process_update
    handler.handle_update(update, self)
  File "/Users/nermohin/anaconda3/lib/python3.7/site-packages/telegram/ext/commandhandler.py", line 173, in handle_update
    return self.callback(dispatcher.bot, update, **optional_args)
  File "bot.py", line 23, in planet_position
    update.message.reply_text(ephem.constellation(ephem.Earh('2019/05/26')))
AttributeError: module 'ephem' has no attribute 'Earh'
telegram.ext.updater - INFO - Received signal 2 (SIGINT), stopping...
telegram.ext.dispatcher - ERROR - An uncaught error was raised while processing the update
Traceback (most recent call last):
  File "/Users/nermohin/anaconda3/lib/python3.7/site-packages/telegram/ext/dispatcher.py", line 279, in process_update
    handler.handle_update(update, self)
  File "/Users/nermohin/anaconda3/lib/python3.7/site-packages/telegram/ext/commandhandler.py", line 173, in handle_update
    return self.callback(dispatcher.bot, update, **optional_args)
  File "bot.py", line 23, in planet_position
    update.message.reply_text(ephem.constellation(ephem.Earth('2019/05/26')))
AttributeError: module 'ephem' has no attribute 'Earth'
telegram.ext.updater - INFO - Received signal 2 (SIGINT), stopping...
telegram.ext.updater - INFO - Received signal 2 (SIGINT), stopping...
telegram.ext.updater - INFO - Received signal 2 (SIGINT), stopping...
